<?xml version="1.0"?>
<robot name="my_bot" xmlns:xacro="http://www.ros.org/wiki/xacro">

    <xacro:include filename="inertia.urdf.xacro"/>
    <xacro:include filename="gazebo.xacro"/>

    <link name="base_link">
    </link>

    <joint name="chassis_joint" type="fixed">
        <origin xyz="0.0 0.0 0.0" rpy="0.0 0.0 0.0"/>
        <parent link="base_link"/>
        <child link="chassis"/>
    </joint>

    <link name="chassis">
        <xacro:inertial_box mass="0.5" x="0.3" y="0.3" z="0.1">
            <origin xyz="0.0 0 0.0" rpy="0 0 0"/>
        </xacro:inertial_box>

        <visual name="">
            <origin xyz="0.0 0.0 0.0" rpy="0.0 0.0 0.0"/>
            <geometry>
                <box size="0.3 0.3 0.1"/>
            </geometry>
            <material name="">
                <color rgba="1.0 0.0 0.0 1.0"/>
            </material>
        </visual>
        <collision>
           <origin xyz="0.0 0.0 0.0" rpy="0.0 0.0 0.0"/>
            <geometry>
                <box size="0.3 0.3 0.1"/>
            </geometry>
        </collision>
    </link>

    <joint name="left_wheel_joint" type="continuous">
        <origin xyz="-0.05 0.18 0.0" rpy="-1.57 0.0 0.0"/>
        <parent link="chassis"/>
        <child link="left_wheel"/>
        <axis xyz="0.0 0.0 1.0"/>
    </joint>

    <link name="left_wheel">
        <xacro:inertial_cylinder mass="0.1" length="0.05" radius="0.1">
            <origin xyz="0.0 0 0.0" rpy="0 0 0"/>
        </xacro:inertial_cylinder>
        <visual name="">
            <origin xyz="0.0 0.0 0.0" rpy="0 0.0 0.0"/>
            <geometry>
                <cylinder radius="0.1" length="0.05"/>
            </geometry>
            <material name="">
                <color rgba="1.0 1.0 0.0 1.0"/>
            </material>
        </visual>
        <collision>
           <origin xyz="0.0 0.0 0.0" rpy="0 0.0 0.0"/>
            <geometry>
                <cylinder radius="0.1" length="0.05"/>
            </geometry>
        </collision>
    </link>
    
    <joint name="right_wheel_joint" type="continuous">
        <origin xyz="-0.05 -0.18 0.0" rpy="1.57 0.0 0.0"/>
        <parent link="chassis"/>
        <child link="right_wheel"/>
        <axis xyz="0.0 0.0 -1.0"/>
    </joint>

    <link name="right_wheel">
        <xacro:inertial_cylinder mass="0.1" length="0.05" radius="0.1">
            <origin xyz="0.0 0 0.0" rpy="0 0 0"/>
        </xacro:inertial_cylinder>
        <visual name="">
            <origin xyz="0.0 0.0 0.0" rpy="0 0.0 0.0"/>
            <geometry>
                <cylinder radius="0.1" length="0.05"/>
            </geometry>
            <material name="">
                <color rgba="1.0 1.0 0.0 1.0"/>
            </material>
        </visual>
        <collision>
            <origin xyz="0.0 0.0 0.0" rpy="0 0.0 0.0"/>
            <geometry>
                <cylinder radius="0.1" length="0.05"/>
            </geometry>
        </collision>
    </link>

    <joint name="castor_joint" type="fixed">
        <origin xyz="0.1 0.0 -0.05" rpy="0.0 0.0 0.0"/>
        <parent link="chassis"/>
        <child link="castor"/>
    </joint>

    <link name="castor">
        <xacro:inertial_sphere mass="0.1" radius="0.05">
            <origin xyz="0.0 0 0.0" rpy="0 0 0"/>
        </xacro:inertial_sphere>
        <visual name="">
            <origin xyz="0.0 0.0 0.0" rpy="0.0 0.0 0.0"/>
            <geometry>
                <sphere radius="0.05"/>
            </geometry>
            <material name="">
                <color rgba="1.0 1.0 0.0 1.0"/>
                <texture filename=""/>
            </material>
        </visual>
        <collision>
             <origin xyz="0.0 0.0 0.0" rpy="0.0 0.0 0.0"/>
            <geometry>
                <sphere radius="0.05"/>
            </geometry>
        </collision>
    </link>

    <joint name="laser_link" type="fixed">
        <origin xyz="0.1 0.0 0.11" rpy="0.0 0.0 0.0"/>
        <parent link="chassis"/>
        <child link="laser"/>
    </joint>

    <link name="laser">
        <xacro:inertial_cylinder mass="0.1" length="0.03" radius="0.05">
            <origin xyz="0.0 0 0.0" rpy="0 0 0"/>
        </xacro:inertial_cylinder>
        <visual name="">
            <origin xyz="0.0 0.0 0.0" rpy="0.0 0.0 0.0"/>
            <geometry>
                <!-- <box size="0.1 0.1 0.03"/> -->
                <cylinder radius="0.05" length="0.03"/>
            </geometry>
                <color rgba="1.0 0.0 0.0 0.0"/>
            <material name="">
                <color rgba="1.0 1.0 0.0 1.0"/>
                <texture filename=""/>
            </material>
        </visual>
        <collision>
            <origin xyz="0.0 0.0 0.0" rpy="0.0 0.0 0.0"/>
            <geometry>
                <box size="0.1 0.1 0.03"/>
            </geometry>
        </collision>
    </link>

    <joint name="camera_joint" type="fixed">
        <origin xyz="0.15 0.0 0.07" rpy="0.0 0.0 0.0"/>
        <parent link="chassis"/>
        <child link="camera"/>
    </joint>

    <link name="camera">
        <xacro:inertial_box mass="0.05" x="0.01" y="0.03" z="0.03">
            <origin xyz="0.0 0 0.0" rpy="0 0 0"/>
        </xacro:inertial_box>
        <visual name="">
            <origin xyz="0.0 0.0 0.0" rpy="0.0 0.0 0.0"/>
            <geometry>
                <box size="0.01 0.03 0.03"/>
            </geometry>
            <material name="">
                <color rgba="1.0 1.0 0.0 1.0"/>
                <texture filename=""/>
            </material>
        </visual>
        <collision>
            <origin xyz="0.0 0.0 0.0" rpy="0.0 0.0 0.0"/>
            <geometry>
                <box size="0.01 0.03 0.03"/>
            </geometry>
        </collision>
    </link>
    
</robot>